Workbook

Sheet Final
A1: Equipo | B1: Posición | C1: Nombre | D1: Foto (URL) | E1: Licencia | F1: País | G1: Fecha de nacimiento | H1: Altura (cm) | I1: Año fin de contrato | J1: Origen | K1: Descripción | L1: Vídeo (URL de YouTube)
A2: Valencia Basket | B2: B | C2: TJ Shorts | D2: https://media-cdn.cortextech.io/c0323c00-43ae-41c3-ba0a-cffbb4e3854b.png | E2: EUR | F2: Estados Unidos | G2: 35718 | H2: 175 | I2: 2028 | J2: Fichaje | N2: =IFERROR(VLOOKUP($C2,prova!$A$1:$D$250,2,FALSE),"") -> https://media-cdn.cortextech.io/c0323c00-43ae-41c3-ba0a-cffbb4e3854b.png | O2: =IFERROR(VLOOKUP($C2,prova!$A$1:$D$250,3,FALSE),"") -> 35718 | P2: =IFERROR(VLOOKUP($C2,prova!$A$1:$D$250,4,FALSE),"") -> 175
A3: Valencia Basket | B3: B | C3: Mario Saint-Supéry | D3: http://assets.fiba.basketball/image/upload/w_2000/f_auto/q_auto/v1731335669/ixnotudf6nlodgl1l3c5.png | E3: JFL | F3: España | G3: 38821 | H3: 192 | I3: 2030 | J3: Fichaje | N3: =IFERROR(VLOOKUP($C3,prova!$A$1:$D$250,2,FALSE),"") -> http://assets.fiba.basketball/image/upload/w_2000/f_auto/q_auto/v1731335669/ixnotudf6nlodgl1l3c5.png | O3: =IFERROR(VLOOKUP($C3,prova!$A$1:$D$250,3,FALSE),"") -> 38821 | P3: =IFERROR(VLOOKUP($C3,prova!$A$1:$D$250,4,FALSE),"") -> 192
A4: Valencia Basket | B4: B | C4: Álvaro Cárdenas | D4: https://static.acb.com/media/PRO/00/00/91/84/35/0000918435_lpr_transparent.webp | E4: JFL | F4: España | G4: 37375 | H4: 187 | I4: 2027 | J4: Sigue | N4: =IFERROR(VLOOKUP($C4,prova!$A$1:$D$250,2,FALSE),"") -> https://static.acb.com/media/PRO/00/00/91/84/35/0000918435_lpr_transparent.webp | O4: =IFERROR(VLOOKUP($C4,prova!$A$1:$D$250,3,FALSE),"") -> 37375 | P4: =IFERROR(VLOOKUP($C4,prova!$A$1:$D$250,4,FALSE),"") -> 187
A5: Valencia Basket | B5: E | C5: Armoni Brooks | D5: https://media-cdn.cortextech.io/8c4d5e17-01aa-4f77-99b1-207d7c82d195.png | E5: EXT | F5: Estados Unidos | G5: 35951 | H5: 194 | I5: 2027 | J5: Cesión | N5: =IFERROR(VLOOKUP($C5,prova!$A$1:$D$250,2,FALSE),"") -> https://media-cdn.cortextech.io/8c4d5e17-01aa-4f77-99b1-207d7c82d195.png | O5: =IFERROR(VLOOKUP($C5,prova!$A$1:$D$250,3,FALSE),"") -> 35951 | P5: =IFERROR(VLOOKUP($C5,prova!$A$1:$D$250,4,FALSE),"") -> 194
A6: Valencia Basket | B6: E | C6: Omari Moore | D6: https://static.acb.com/media/PRO/00/00/83/31/64/0000833164_lpr_transparent.webp | E6: EUR | F6: Estados Unidos | G6: 36787 | H6: 198 | I6: 2027 | J6: Sigue | N6: =IFERROR(VLOOKUP($C6,prova!$A$1:$D$250,2,FALSE),"") -> https://static.acb.com/media/PRO/00/00/83/31/64/0000833164_lpr_transparent.webp | O6: =IFERROR(VLOOKUP($C6,prova!$A$1:$D$250,3,FALSE),"") -> 36787 | P6: =IFERROR(VLOOKUP($C6,prova!$A$1:$D$250,4,FALSE),"") -> 198
A7: Valencia Basket | B7: E | C7: Gonzalo Corbalán | D7: https://static.acb.com/media/PRO/00/00/83/26/60/0000832660_lpr_transparent.webp | E7: EUR | F7: Argentina | G7: 37318 | H7: 193 | I7: 2029 | J7: Fichaje | N7: =IFERROR(VLOOKUP($C7,prova!$A$1:$D$250,2,FALSE),"") -> https://static.acb.com/media/PRO/00/00/83/26/60/0000832660_lpr_transparent.webp | O7: =IFERROR(VLOOKUP($C7,prova!$A$1:$D$250,3,FALSE),"") -> 37318 | P7: =IFERROR(VLOOKUP($C7,prova!$A$1:$D$250,4,FALSE),"") -> 193
A8: Valencia Basket | B8: E | C8: Lucas Marí | D8: https://acb.com/_next/image?url=https%3A%2F%2Fstatic.acb.com%2Fmedia%2FPRO%2F00%2F00%2F56%2F69%2F31%2F0000566931_lpr_transparent.webp&w=1200&q=75 | E8: JFL | F8: España | G8: 38645 | H8: 197 | I8: 2028 | J8: Vuelve de cesión | N8: =IFERROR(VLOOKUP($C8,prova!$A$1:$D$250,2,FALSE),"") -> https://acb.com/_next/image?url=https%3A%2F%2Fstatic.acb.com%2Fmedia%2FPRO%2F00%2F00%2F56%2F69%2F31%2F0000566931_lpr_transparent.webp&w=1200&q=75 | O8: =IFERROR(VLOOKUP($C8,prova!$A$1:$D$250,3,FALSE),"") -> 38645 | P8: =IFERROR(VLOOKUP($C8,prova!$A$1:$D$250,4,FALSE),"") -> 197
A9: Valencia Basket | B9: A | C9: Kameron Taylor | D9: https://static.acb.com/media/PRO/00/00/83/30/45/0000833045_lpr_transparent.webp | E9: EXT | F9: Estados Unidos | G9: 34612 | H9: 198 | I9: 2028 | J9: Sigue | N9: =IFERROR(VLOOKUP($C9,prova!$A$1:$D$250,2,FALSE),"") -> https://static.acb.com/media/PRO/00/00/83/30/45/0000833045_lpr_transparent.webp | O9: =IFERROR(VLOOKUP($C9,prova!$A$1:$D$250,3,FALSE),"") -> 34612 | P9: =IFERROR(VLOOKUP($C9,prova!$A$1:$D$250,4,FALSE),"") -> 198
A10: Valencia Basket | B10: A | C10: Josep Puerto | D10: https://static.acb.com/media/PRO/00/00/83/30/24/0000833024_lpr_transparent.webp | E10: JFL | F10: España | G10: 36227 | H10: 199 | I10: 2027 | J10: Sigue | N10: =IFERROR(VLOOKUP($C10,prova!$A$1:$D$250,2,FALSE),"") -> https://static.acb.com/media/PRO/00/00/83/30/24/0000833024_lpr_transparent.webp | O10: =IFERROR(VLOOKUP($C10,prova!$A$1:$D$250,3,FALSE),"") -> 36227 | P10: =IFERROR(VLOOKUP($C10,prova!$A$1:$D$250,4,FALSE),"") -> 199
A11: Valencia Basket | B11: AP | C11: Dylan Osetkowski | D11: https://media-cdn.cortextech.io/d5277fb5-a978-453b-bfcb-731c5704609c.png | E11: EUR | F11: Estados Unidos | G11: 35285 | H11: 206 | I11: 2028 | J11: Fichaje | N11: =IFERROR(VLOOKUP($C11,prova!$A$1:$D$250,2,FALSE),"") -> https://media-cdn.cortextech.io/d5277fb5-a978-453b-bfcb-731c5704609c.png | O11: =IFERROR(VLOOKUP($C11,prova!$A$1:$D$250,3,FALSE),"") -> 35285 | P11: =IFERROR(VLOOKUP($C11,prova!$A$1:$D$250,4,FALSE),"") -> 206
A12: Valencia Basket | B12: AP | C12: Mo Gueye | D12: https://cdn.nba.com/headshots/nba/latest/1040x760/1631243.png | E12: COT | F12: Estados Unidos | G12: 37569 | H12: 211 | I12: 2027 | J12: Fichaje | N12: =IFERROR(VLOOKUP($C12,prova!$A$1:$D$250,2,FALSE),"") -> https://cdn.nba.com/headshots/nba/latest/1040x760/1631243.png | O12: =IFERROR(VLOOKUP($C12,prova!$A$1:$D$250,3,FALSE),"") -> 37569 | P12: =IFERROR(VLOOKUP($C12,prova!$A$1:$D$250,4,FALSE),"") -> 211
A13: Valencia Basket | B13: P | C13: Nate Reuvers | D13: https://static.acb.com/media/PRO/00/00/83/30/95/0000833095_lpr_transparent.webp | E13: EUR | F13: Estados Unidos | G13: 36068 | H13: 211 | I13: 2028 | J13: Sigue | N13: =IFERROR(VLOOKUP($C13,prova!$A$1:$D$250,2,FALSE),"") -> https://static.acb.com/media/PRO/00/00/83/30/95/0000833095_lpr_transparent.webp | O13: =IFERROR(VLOOKUP($C13,prova!$A$1:$D$250,3,FALSE),"") -> 36068 | P13: =IFERROR(VLOOKUP($C13,prova!$A$1:$D$250,4,FALSE),"") -> 211
... A64: Asisa Joventut | B64: AP | C64: Emir Sulejmanovic | D64: https://static.acb.com/media/PRO/00/00/82/68/47/0000826847_lpr_transparent.webp | E64: EUR | F64: Bosnia y Herzegovina | G64: 34893 | H64: 205 | I64: 2028 | J64: Fichaje | N64: =IFERROR(VLOOKUP($C64,prova!$A$1:$D$250,2,FALSE),"") -> https://static.acb.com/media/PRO/00/00/82/68/47/0000826847_lpr_transparent.webp | O64: =IFERROR(VLOOKUP($C64,prova!$A$1:$D$250,3,FALSE),"") -> 34893 | P64: =IFERROR(VLOOKUP($C64,prova!$A$1:$D$250,4,FALSE),"") -> 205
A65: Asisa Joventut | B65: P | C65: Dane Erikstrup | D65: http://assets.fiba.basketball/image/upload/w_2000/f_auto/q_auto/v1731335669/ixnotudf6nlodgl1l3c5.png | E65: EUR | F65: Dinamarca | G65: 37714 | H65: 212 | I65: - | J65: Fichaje | N65: =IFERROR(VLOOKUP($C65,prova!$A$1:$D$250,2,FALSE),"") -> http://assets.fiba.basketball/image/upload/w_2000/f_auto/q_auto/v1731335669/ixnotudf6nlodgl1l3c5.png | O65: =IFERROR(VLOOKUP($C65,prova!$A$1:$D$250,3,FALSE),"") -> 37714 | P65: =IFERROR(VLOOKUP($C65,prova!$A$1:$D$250,4,FALSE),"") -> 212
A66: Asisa Joventut | B66: P | C66: Ante Tomic | D66: https://static.acb.com/media/PRO/00/00/88/22/39/0000882239_lpr_transparent.webp | E66: EUR | F66: Croacia | G66: 31825 | H66: 217 | I66: 2027 | J66: Sigue | N66: =IFERROR(VLOOKUP($C66,prova!$A$1:$D$250,2,FALSE),"") -> https://static.acb.com/media/PRO/00/00/88/22/39/0000882239_lpr_transparent.webp | O66: =IFERROR(VLOOKUP($C66,prova!$A$1:$D$250,3,FALSE),"") -> 31825 | P66: =IFERROR(VLOOKUP($C66,prova!$A$1:$D$250,4,FALSE),"") -> 217
A67: Asisa Joventut | B67: P | C67: Simon Birgander | D67: https://static.acb.com/media/PRO/00/00/88/25/79/0000882579_lpr_transparent.webp | E67: EUR | F67: Suecia | G67: 35726 | H67: 209 | I67: 2027 | J67: Sigue | N67: =IFERROR(VLOOKUP($C67,prova!$A$1:$D$250,2,FALSE),"") -> https://static.acb.com/media/PRO/00/00/88/25/79/0000882579_lpr_transparent.webp | O67: =IFERROR(VLOOKUP($C67,prova!$A$1:$D$250,3,FALSE),"") -> 35726 | P67: =IFERROR(VLOOKUP($C67,prova!$A$1:$D$250,4,FALSE),"") -> 209
A68: Surne Bilbao | B68: B | C68: Harald Frey | D68: https://static.acb.com/media/PRO/00/00/83/57/75/0000835775_lpr_transparent.webp | E68: EUR | F68: Noruega | G68: 35577 | H68: 188 | I68: 2029 | J68: Renovación | N68: =IFERROR(VLOOKUP($C68,prova!$A$1:$D$250,2,FALSE),"") -> https://static.acb.com/media/PRO/00/00/83/57/75/0000835775_lpr_transparent.webp | O68: =IFERROR(VLOOKUP($C68,prova!$A$1:$D$250,3,FALSE),"") -> 35577 | P68: =IFERROR(VLOOKUP($C68,prova!$A$1:$D$250,4,FALSE),"") -> 188
A69: Surne Bilbao | B69: B | C69: Adam Somogyi | D69: http://assets.fiba.basketball/image/upload/w_2000/f_auto/q_auto/v1731335669/ixnotudf6nlodgl1l3c5.png | E69: JFL | F69: Hungría | G69: 36707 | H69: 190 | I69: 2028 | J69: Fichaje | N69: =IFERROR(VLOOKUP($C69,prova!$A$1:$D$250,2,FALSE),"") -> http://assets.fiba.basketball/image/upload/w_2000/f_auto/q_auto/v1731335669/ixnotudf6nlodgl1l3c5.png | O69: =IFERROR(VLOOKUP($C69,prova!$A$1:$D$250,3,FALSE),"") -> 36707 | P69: =IFERROR(VLOOKUP($C69,prova!$A$1:$D$250,4,FALSE),"") -> 190
A70: Surne Bilbao | B70: B | C70: Dan Duscak | D70: https://imagenes.feb.es/Foto.aspx?c=2822575 | E70: JFL | F70: Eslovenia | G70: 37439 | H70: 185 | I70: 2028 | J70: Fichaje | N70: =IFERROR(VLOOKUP($C70,prova!$A$1:$D$250,2,FALSE),"") -> https://imagenes.feb.es/Foto.aspx?c=2822575 | O70: =IFERROR(VLOOKUP($C70,prova!$A$1:$D$250,3,FALSE),"") -> 37439 | P70: =IFERROR(VLOOKUP($C70,prova!$A$1:$D$250,4,FALSE),"") -> 185
A71: Surne Bilbao | B71: E | C71: Nate Darling | D71: http://assets.fiba.basketball/image/upload/w_2000/f_auto/q_auto/v1731335669/ixnotudf6nlodgl1l3c5.png | E71: EXT | F71: Estados Unidos | G71: 36037 | H71: 190 | I71: 2027 | J71: Fichaje | N71: =IFERROR(VLOOKUP($C71,prova!$A$1:$D$250,2,FALSE),"") -> http://assets.fiba.basketball/image/upload/w_2000/f_auto/q_auto/v1731335669/ixnotudf6nlodgl1l3c5.png | O71: =IFERROR(VLOOKUP($C71,prova!$A$1:$D$250,3,FALSE),"") -> 36037 | P71: =IFERROR(VLOOKUP($C71,prova!$A$1:$D$250,4,FALSE),"") -> 190
A72: Surne Bilbao | B72: E | C72: Margiris Normantas | D72: https://static.acb.com/media/PRO/00/00/83/58/50/0000835850_lpr_transparent.webp | E72: EUR | F72: Lituania | G72: 35365 | H72: 194 | I72: 2028 | J72: Renovación | N72: =IFERROR(VLOOKUP($C72,prova!$A$1:$D$250,2,FALSE),"") -> https://static.acb.com/media/PRO/00/00/83/58/50/0000835850_lpr_transparent.webp | O72: =IFERROR(VLOOKUP($C72,prova!$A$1:$D$250,3,FALSE),"") -> 35365 | P72: =IFERROR(VLOOKUP($C72,prova!$A$1:$D$250,4,FALSE),"") -> 194
A73: Surne Bilbao | B73: A | C73: Darrun Hilliard | D73: https://static.acb.com/media/PRO/00/00/83/57/43/0000835743_lpr_transparent.webp | E73: EXT | F73: Estados Unidos | G73: 34072 | H73: 198 | I73: 2028 | J73: Renovación | N73: =IFERROR(VLOOKUP($C73,prova!$A$1:$D$250,2,FALSE),"") -> https://static.acb.com/media/PRO/00/00/83/57/43/0000835743_lpr_transparent.webp | O73: =IFERROR(VLOOKUP($C73,prova!$A$1:$D$250,3,FALSE),"") -> 34072 | P73: =IFERROR(VLOOKUP($C73,prova!$A$1:$D$250,4,FALSE),"") -> 198
A74: Surne Bilbao | B74: A | C74: Aleix Font | D74: https://static.acb.com/media/PRO/00/00/83/56/64/0000835664_lpr_transparent.webp | E74: JFL | F74: España | G74: 35865 | H74: 194 | I74: 2029 | J74: Renovación | N74: =IFERROR(VLOOKUP($C74,prova!$A$1:$D$250,2,FALSE),"") -> https://static.acb.com/media/PRO/00/00/83/56/64/0000835664_lpr_transparent.webp | O74: =IFERROR(VLOOKUP($C74,prova!$A$1:$D$250,3,FALSE),"") -> 35865 | P74: =IFERROR(VLOOKUP($C74,prova!$A$1:$D$250,4,FALSE),"") -> 194
A75: Surne Bilbao | B75: A | C75: Manex Ansorregi | D75: https://imagenes.feb.es/Foto.aspx?c=2082685 | E75: JFL | F75: España | G75: 37357 | H75: 196 | I75: 2028 | J75: Fichaje | N75: =IFERROR(VLOOKUP($C75,prova!$A$1:$D$250,2,FALSE),"") -> https://imagenes.feb.es/Foto.aspx?c=2082685 | O75: =IFERROR(VLOOKUP($C75,prova!$A$1:$D$250,3,FALSE),"") -> 37357 | P75: =IFERROR(VLOOKUP($C75,prova!$A$1:$D$250,4,FALSE),"") -> 196
A76: Surne Bilbao | B76: AP | C76: Martin Krampelj | D76: https://static.acb.com/media/PRO/00/00/83/58/73/0000835873_lpr_transparent.webp | E76: EUR | F76: Eslovenia | G76: 34768 | H76: 206 | I76: 2028 | J76: Renovación | N76: =IFERROR(VLOOKUP($C76,prova!$A$1:$D$250,2,FALSE),"") -> https://static.acb.com/media/PRO/00/00/83/58/73/0000835873_lpr_transparent.webp | O76: =IFERROR(VLOOKUP($C76,prova!$A$1:$D$250,3,FALSE),"") -> 34768 | P76: =IFERROR(VLOOKUP($C76,prova!$A$1:$D$250,4,FALSE),"") -> 206
A77: Surne Bilbao | B77: AP | C77: Luke Petrasek | D77: https://static.acb.com/media/PRO/00/00/83/58/32/0000835832_lpr_transparent.webp | E77: EUR | F77: Estados Unidos | G77: 34928 | H77: 208 | I77: 2028 | J77: Renovación | N77: =IFERROR(VLOOKUP($C77,prova!$A$1:$D$250,2,FALSE),"") -> https://static.acb.com/media/PRO/00/00/83/58/32/0000835832_lpr_transparent.webp | O77: =IFERROR(VLOOKUP($C77,prova!$A$1:$D$250,3,FALSE),"") -> 34928 | P77: =IFERROR(VLOOKUP($C77,prova!$A$1:$D$250,4,FALSE),"") -> 208
... A99: Unicaja | B99: E | C99: Nihad Djedovic | D99: https://static.acb.com/media/PRO/00/00/82/70/48/0000827048_lpr_transparent.webp | E99: JFL | F99: Alemania | G99: 32885 | H99: 197 | I99: 2027 | J99: Renovación | N99: =IFERROR(VLOOKUP($C99,prova!$A$1:$D$250,2,FALSE),"") -> https://static.acb.com/media/PRO/00/00/82/70/48/0000827048_lpr_transparent.webp | O99: =IFERROR(VLOOKUP($C99,prova!$A$1:$D$250,3,FALSE),"") -> 32885 | P99: =IFERROR(VLOOKUP($C99,prova!$A$1:$D$250,4,FALSE),"") -> 197
A100: Unicaja | B100: A | C100: Simonas Lukosius | D100: http://assets.fiba.basketball/image/upload/w_2000/f_auto/q_auto/v1731335669/ixnotudf6nlodgl1l3c5.png | E100: EUR | F100: Lituania | G100: 37481 | H100: 198 | I100: - | J100: Cesión | N100: =IFERROR(VLOOKUP($C100,prova!$A$1:$D$250,2,FALSE),"") -> http://assets.fiba.basketball/image/upload/w_2000/f_auto/q_auto/v1731335669/ixnotudf6nlodgl1l3c5.png | O100: =IFERROR(VLOOKUP($C100,prova!$A$1:$D$250,3,FALSE),"") -> 37481 | P100: =IFERROR(VLOOKUP($C100,prova!$A$1:$D$250,4,FALSE),"") -> 198
A101: Unicaja | B101: A | C101: Ignas Brazdeikis | D101: https://media-cdn.cortextech.io/32aea757-dc80-4848-82f4-525b77e0eb0d.png | E101: EUR | F101: Lituania | G101: 36168 | H101: 201 | I101: 2027 | J101: Fichaje | N101: =IFERROR(VLOOKUP($C101,prova!$A$1:$D$250,2,FALSE),"") -> https://media-cdn.cortextech.io/32aea757-dc80-4848-82f4-525b77e0eb0d.png | O101: =IFERROR(VLOOKUP($C101,prova!$A$1:$D$250,3,FALSE),"") -> 36168 | P101: =IFERROR(VLOOKUP($C101,prova!$A$1:$D$250,4,FALSE),"") -> 201
A102: Unicaja | B102: A | C102: Jonathan Barreiro | D102: https://static.acb.com/media/PRO/00/00/82/69/24/0000826924_lpr_transparent.webp | E102: JFL | F102: España | G102: 35446 | H102: 203 | I102: 2027 | J102: Renovación | N102: =IFERROR(VLOOKUP($C102,prova!$A$1:$D$250,2,FALSE),"") -> https://static.acb.com/media/PRO/00/00/82/69/24/0000826924_lpr_transparent.webp | O102: =IFERROR(VLOOKUP($C102,prova!$A$1:$D$250,3,FALSE),"") -> 35446 | P102: =IFERROR(VLOOKUP($C102,prova!$A$1:$D$250,4,FALSE),"") -> 203
A103: Unicaja | B103: AP | C103: Amine Noua | D103: https://media-cdn.cortextech.io/1dU3kpCqReRp93/1BSdBWIjCbqck7/eb206bb3-3e1f-488d-b1fe-ecfcbab13249.png | E103: EUR | F103: Francia | G103: 35468 | H103: 202 | I103: 2028 | J103: Fichaje | N103: =IFERROR(VLOOKUP($C103,prova!$A$1:$D$250,2,FALSE),"") -> https://media-cdn.cortextech.io/1dU3kpCqReRp93/1BSdBWIjCbqck7/eb206bb3-3e1f-488d-b1fe-ecfcbab13249.png | O103: =IFERROR(VLOOKUP($C103,prova!$A$1:$D$250,3,FALSE),"") -> 35468 | P103: =IFERROR(VLOOKUP($C103,prova!$A$1:$D$250,4,FALSE),"") -> 202
A104: Unicaja | B104: AP | C104: Tyson Pérez | D104: https://static.acb.com/media/PRO/00/00/82/71/45/0000827145_lpr_transparent.webp | E104: JFL | F104: España | G104: 35093 | H104: 202 | I104: 2029 | J104: Sigue | N104: =IFERROR(VLOOKUP($C104,prova!$A$1:$D$250,2,FALSE),"") -> https://static.acb.com/media/PRO/00/00/82/71/45/0000827145_lpr_transparent.webp | O104: =IFERROR(VLOOKUP($C104,prova!$A$1:$D$250,3,FALSE),"") -> 35093 | P104: =IFERROR(VLOOKUP($C104,prova!$A$1:$D$250,4,FALSE),"") -> 202
A105: Unicaja | B105: P | C105: Willy Hernangómez | D105: https://static.acb.com/media/PRO/00/00/82/98/51/0000829851_lpr_transparent.webp | E105: JFL | F105: España | G105: 34481 | H105: 210 | I105: 2027 | J105: Fichaje | N105: =IFERROR(VLOOKUP($C105,prova!$A$1:$D$250,2,FALSE),"") -> https://static.acb.com/media/PRO/00/00/82/98/51/0000829851_lpr_transparent.webp | O105: =IFERROR(VLOOKUP($C105,prova!$A$1:$D$250,3,FALSE),"") -> 34481 | P105: =IFERROR(VLOOKUP($C105,prova!$A$1:$D$250,4,FALSE),"") -> 210
A106: Unicaja | B106: P | C106: David Kravish | D106: https://static.acb.com/media/PRO/00/00/82/68/13/0000826813_lpr_transparent.webp | E106: EUR | F106: Estados Unidos | G106: 33859 | H106: 208 | I106: 2028 | J106: Sigue | N106: =IFERROR(VLOOKUP($C106,prova!$A$1:$D$250,2,FALSE),"") -> https://static.acb.com/media/PRO/00/00/82/68/13/0000826813_lpr_transparent.webp | O106: =IFERROR(VLOOKUP($C106,prova!$A$1:$D$250,3,FALSE),"") -> 33859 | P106: =IFERROR(VLOOKUP($C106,prova!$A$1:$D$250,4,FALSE),"") -> 208
A107: Unicaja | B107: P | C107: Yannick Nzosa | D107: https://static.acb.com/media/PRO/00/00/83/28/52/0000832852_lpr_transparent.webp | E107: JFL | F107: RD Congo | G107: 37940 | H107: 208 | I107: 2027 | J107: Vuelve de cesión | N107: =IFERROR(VLOOKUP($C107,prova!$A$1:$D$250,2,FALSE),"") -> https://static.acb.com/media/PRO/00/00/83/28/52/0000832852_lpr_transparent.webp | O107: =IFERROR(VLOOKUP($C107,prova!$A$1:$D$250,3,FALSE),"") -> 37940 | P107: =IFERROR(VLOOKUP($C107,prova!$A$1:$D$250,4,FALSE),"") -> 208
A108: Kids&Us Manresa | B108: B | C108: Hugo Benítez | D108: https://static.acb.com/media/PRO/00/00/82/74/22/0000827422_lpr_transparent.webp | E108: EUR | F108: Francia | G108: 36911 | H108: 192 | I108: 2028 | J108: Sigue | N108: =IFERROR(VLOOKUP($C108,prova!$A$1:$D$250,2,FALSE),"") -> https://static.acb.com/media/PRO/00/00/82/74/22/0000827422_lpr_transparent.webp | O108: =IFERROR(VLOOKUP($C108,prova!$A$1:$D$250,3,FALSE),"") -> 36911 | P108: =IFERROR(VLOOKUP($C108,prova!$A$1:$D$250,4,FALSE),"") -> 192
A109: Kids&Us Manresa | B109: B | C109: Ferran Bassas | D109: https://static.acb.com/media/PRO/00/00/86/74/90/0000867490_lpr_transparent.webp | E109: JFL | F109: España | G109: 33723 | H109: 181 | I109: 2028 | J109: Renovación | N109: =IFERROR(VLOOKUP($C109,prova!$A$1:$D$250,2,FALSE),"") -> https://static.acb.com/media/PRO/00/00/86/74/90/0000867490_lpr_transparent.webp | O109: =IFERROR(VLOOKUP($C109,prova!$A$1:$D$250,3,FALSE),"") -> 33723 | P109: =IFERROR(VLOOKUP($C109,prova!$A$1:$D$250,4,FALSE),"") -> 181
A110: Kids&Us Manresa | B110: B | C110: Rafa Villar | D110: https://static.acb.com/media/PRO/00/00/83/36/76/0000833676_lpr_transparent.webp | E110: JFL | F110: España | G110: 38208 | H110: 191 | I110: 2028 | J110: Fichaje | N110: =IFERROR(VLOOKUP($C110,prova!$A$1:$D$250,2,FALSE),"") -> https://static.acb.com/media/PRO/00/00/83/36/76/0000833676_lpr_transparent.webp | O110: =IFERROR(VLOOKUP($C110,prova!$A$1:$D$250,3,FALSE),"") -> 38208 | P110: =IFERROR(VLOOKUP($C110,prova!$A$1:$D$250,4,FALSE),"") -> 191
A111: Kids&Us Manresa | B111: B | C111: Lucas Beaufort | D111: https://www.proballers.com/media/cache/headshot_600/player/headshot/75959.png | E111: EUR | F111: Francia | G111: 37400 | H111: 192 | I111: 2029 | J111: Fichaje | N111: =IFERROR(VLOOKUP($C111,prova!$A$1:$D$250,2,FALSE),"") -> https://www.proballers.com/media/cache/headshot_600/player/headshot/75959.png | O111: =IFERROR(VLOOKUP($C111,prova!$A$1:$D$250,3,FALSE),"") -> 37400 | P111: =IFERROR(VLOOKUP($C111,prova!$A$1:$D$250,4,FALSE),"") -> 192
...

Sheet otros
A1: jugador | B1: foto | C1: dob | D1: altura | E1: link
A2: DJ Stewart | B2: https://media-cdn.cortextech.io/dd9bcf27-807d-4de7-8797-5b659b95eb0a.png | C2: 36369 | D2: 196 | E2: https://www.euroleaguebasketball.net/en/eurocup/players/dj-stewart/012700/
A3: Umoja Gibson | B3: https://media-cdn.cortextech.io/be7ac987-733b-4c31-b7d0-a679cc9bf90e.png | C3: 35980 | D3: 182 | E3: https://www.euroleaguebasketball.net/en/eurocup/players/umoja-gibson/013855/
A4: Amine Noua | B4: https://media-cdn.cortextech.io/1dU3kpCqReRp93/1BSdBWIjCbqck7/eb206bb3-3e1f-488d-b1fe-ecfcbab13249.png | C4: 35468 | D4: 202 | E4: https://www.euroleaguebasketball.net/en/eurocup/players/amine-noua/006068/
A5: Yordan Minchev | B5: https://media-cdn.cortextech.io/8b9744f1-350d-400a-b644-a59b83c7e19a.png | C5: 36085 | D5: 205 | E5: https://www.euroleaguebasketball.net/en/eurocup/players/yordan-minchev/007423/
A6: DJ Steward | B6: https://media-cdn.cortextech.io/8163227a-e1a5-4219-907b-196214ad7637.png | C6: 37166 | D6: 188 | E6: https://www.euroleaguebasketball.net/en/eurocup/players/dj-steward/013861/
A7: Christian Sengfelder | B7: https://media-cdn.cortextech.io/5f3afa4d-663f-463d-a1ad-c9fb05a9b2ef.png | C7: 34758 | D7: 201 | E7: https://www.euroleaguebasketball.net/en/eurocup/players/christian-sengfelder/013917/
A8: Balsa Koprivica | B8: https://media-cdn.cortextech.io/c6a7ff2f-a4da-4ac0-9a7c-3236f143336a.png | C8: 36647 | D8: 216 | E8: https://www.euroleaguebasketball.net/en/eurocup/players/balsa-koprivica/011050/
A9: Caleb Homesley | B9: https://media-cdn.cortextech.io/0d3640a2-d499-462b-8d27-02fac053abfc.png | C9: 35396 | D9: 198 | E9: https://www.euroleaguebasketball.net/en/eurocup/players/caleb-homesley/011251/
A10: Lazar Mutic | B10: https://media-cdn.cortextech.io/d71392b0-1f1c-4600-a6cb-172423fbb777.png | C10: 36166 | D10: 201 | E10: https://www.euroleaguebasketball.net/en/eurocup/players/lazar-mutic/013864/
A11: Dmytro Skapintsev | B11: https://media-cdn.cortextech.io/b7a5652c-08e6-4446-a8bd-3dbff1f2034d.png | C11: 35927 | D11: 215 | E11: https://www.euroleaguebasketball.net/en/eurocup/players/dmytro-skapintsev/013905/
A12: TJ Shorts | B12: https://media-cdn.cortextech.io/c0323c00-43ae-41c3-ba0a-cffbb4e3854b.png | C12: 35718 | D12: 175 | E12: https://www.euroleaguebasketball.net/en/euroleague/players/tj-shorts/012608/
A13: Armoni Brooks | B13: https://media-cdn.cortextech.io/8c4d5e17-01aa-4f77-99b1-207d7c82d195.png | C13: 35951 | D13: 194 | E13: https://www.euroleaguebasketball.net/en/euroleague/players/armoni-brooks/013384/
... A21: Leon Radosevic | B21: https://media-cdn.incrowdsports.com/9951cb2d-b0cf-4ffa-8ffd-1a98b44009eb.png | C21: 32930 | D21: 208 | E21: https://www.euroleaguebasketball.net/en/euroleague/players/leon-radosevic/lem/

Sheet prova
A1: nombre | B1: foto | C1: fecha_nacimiento | D1: altura
A2: Chris Duarte | B2: https://static.acb.com/media/PRO/00/00/82/67/55/0000826755_lpr_transparent.webp | C2: 35594 | D2: 196
A3: Markus Howard | B3: https://static.acb.com/media/PRO/00/00/83/35/84/0000833584_lpr_transparent.webp | C3: 36222 | D3: 179
A4: Stefan Joksimovic | B4: https://static.acb.com/media/PRO/00/00/83/37/25/0000833725_lpr_transparent.webp | C4: 39768 | D4: 201
A5: Rodions Kurucs | B5: https://static.acb.com/media/PRO/00/00/83/36/98/0000833698_lpr_transparent.webp | C5: 35831 | D5: 203
A6: Tadas Sedekerskis | B6: https://static.acb.com/media/PRO/00/00/83/37/43/0000833743_lpr_transparent.webp | C6: 35812 | D6: 206
A7: Clément Frisch | B7: https://static.acb.com/media/PRO/00/00/83/34/68/0000833468_lpr_transparent.webp | C7: 37263 | D7: 201
A8: Khalifa Diop | B8: https://static.acb.com/media/PRO/00/00/83/35/40/0000833540_lpr_transparent.webp | C8: 37271 | D8: 215
A9: Juani Marcos | B9: https://static.acb.com/media/PRO/00/00/82/96/38/0000829638_lpr_transparent.webp | C9: 36713 | D9: 190
A10: Michael Forrest | B10: https://static.acb.com/media/PRO/00/00/83/15/30/0000831530_lpr_transparent.webp | C10: 36496 | D10: 183
A11: Dylan Ennis | B11: https://static.acb.com/media/PRO/00/00/83/13/37/0000831337_lpr_transparent.webp | C11: 33598 | D11: 188
A12: Jonah Radebaugh | B12: https://static.acb.com/media/PRO/00/00/83/14/58/0000831458_lpr_transparent.webp | C12: 35598 | D12: 191
A13: Sander Raieste | B13: https://static.acb.com/media/PRO/00/00/83/16/05/0000831605_lpr_transparent.webp | C13: 36250 | D13: 201
... A206: Leon Radosevic | B206: https://media-cdn.incrowdsports.com/9951cb2d-b0cf-4ffa-8ffd-1a98b44009eb.png | C206: 32930 | D206: 208

Sheet acbs
A1: nombre | B1: link
A2: Martin Krampelj | B2: https://acb.com/es/liga/jugadores/martin-krampelj-30000192
A3: Luke Petrasek | B3: https://acb.com/es/liga/jugadores/luke-petrasek-30003947
A4: Tryggvi Hlinason | B4: https://acb.com/es/liga/jugadores/tryggvi-hlinason-20212461
A5: Marcelinho Huertas | B5: https://acb.com/es/liga/jugadores/marcelo-tieppo-20201760
A6: Bruno Fitipaldo | B6: https://acb.com/es/liga/jugadores/bruno-fitipaldo-20212972
A7: Wesley Van Beck | B7: https://acb.com/es/liga/jugadores/wesley-van-beck-30003999
A8: Jaime Fernández Bernabé | B8: https://acb.com/es/liga/jugadores/jaime-fernandez-20204124
A9: Rokas Giedraitis | B9: https://acb.com/es/liga/jugadores/rokas-giedraitis-30000306
A10: Xabi López-Arostegui | B10: https://acb.com/es/liga/jugadores/xabier-lopez-arostegui-20211660
A11: Tim Abromaitis | B11: https://acb.com/es/liga/jugadores/timothy-abromaitis-20211625
A12: Aaron Doornekamp | B12: https://acb.com/es/liga/jugadores/aaron-doornekamp-20212189
... A68: Joel Soriano | B68: https://acb.com/es/liga/jugadores/joel-soriano-30003936
